<robot name="jaco">
  <link name="base_link" />
  <joint name="base_joint" type="fixed">
    <parent link="base_link" />
    <child link="jaco_base_link" />
    <origin xyz="0 0 0" />
  </joint>
  <material name="JacoGrey">
    <color rgba="0.2 0.2 0.9 1.0" />
  </material>
  <link name="jaco_base_link">
    <inertial>
      <mass value="1" />
      
      <origin rpy="0 0 0" xyz="0 0 0.0" />
      <inertia ixx="1" ixy="0" ixz="0" iyy="1" iyz="0" izz="1" />
    </inertial>
    <visual>
      <material name="JacoGrey" />
      
      <geometry>
        <mesh filename="C:/Users/MohammadhoseinAbdoll/vilma-agent/data/models/custom/9580a4cf/vilma_6axis_robot/vilma_6axis_robot/meshes/joint_1.stl" scale="0.001 0.001 0.001" />
      </geometry>
    </visual>
    <collision>
      
      <geometry>
        <mesh filename="C:/Users/MohammadhoseinAbdoll/vilma-agent/data/models/custom/9580a4cf/vilma_6axis_robot/vilma_6axis_robot/meshes/joint_1.stl" scale="0.001 0.001 0.001" />
      </geometry>
    </collision>
  </link>
  <joint name="jaco_joint_1" type="revolute">
    
    <origin rpy="0 0 0" xyz="0 0 0.2725" />
    <axis rpy="0 0 0" xyz="0 0 -1" />
    <parent link="jaco_base_link" />
    <child link="jaco_link_1" />
    <limit effort="30" lower="-3.14159265359" upper="3.14159265359" velocity="5" />
  </joint>
  <link name="jaco_link_1">
    <inertial>
      <mass value="1" />
      <inertia ixx="1" ixy="0" ixz="0" iyy="1" iyz="0" izz="1" />
      <origin />
    </inertial>
    <visual>
      <material name="JacoGrey" />
      <origin rpy="0 0 -1.570796327" xyz="0 0 -0.12" />
      <geometry>
        <mesh filename="C:/Users/MohammadhoseinAbdoll/vilma-agent/data/models/custom/9580a4cf/vilma_6axis_robot/vilma_6axis_robot/meshes/joint_2.stl" scale="0.001 0.001 0.001" />
      </geometry>
    </visual>
    <collision>
      <origin rpy="0 0 -1.570796327" xyz="0 0 -0.12" />
      <geometry>
        <mesh filename="C:/Users/MohammadhoseinAbdoll/vilma-agent/data/models/custom/9580a4cf/vilma_6axis_robot/vilma_6axis_robot/meshes/joint_2.stl" scale="0.001 0.001 0.001" />
      </geometry>
    </collision>
  </link>
  <joint name="jaco_joint_2" type="revolute">
    <origin rpy="-1.570796327 0 0" xyz="0 0 0" />
    <axis xyz="0 0 1" />
    <parent link="jaco_link_1" />
    <child link="jaco_link_2" />
    <limit effort="30" lower="-3.14159265359" upper="3.14159265359" velocity="5" />
  </joint>
  <link name="jaco_link_2">
    <inertial>
      <mass value="1" />
      <inertia ixx="1" ixy="0" ixz="0" iyy="1" iyz="0" izz="1" />
      <origin />
    </inertial>
    <visual>
      <material name="JacoGrey" />
      <origin rpy="0 1.570796327 0" xyz="0 0 0.015" />
      <geometry>
        <mesh filename="C:/Users/MohammadhoseinAbdoll/vilma-agent/data/models/custom/9580a4cf/vilma_6axis_robot/vilma_6axis_robot/meshes/joint_3.stl" scale="0.001 0.001 0.001" />
      </geometry>
    </visual>
    <collision>
      <origin rpy="0 1.570796327 0" xyz="0 0 0.015" />
      <geometry>
        <mesh filename="C:/Users/MohammadhoseinAbdoll/vilma-agent/data/models/custom/9580a4cf/vilma_6axis_robot/vilma_6axis_robot/meshes/joint_3.stl" scale="0.001 0.001 0.001" />
      </geometry>
    </collision>
  </link>
  <joint name="jaco_joint_3" type="revolute">
    <origin rpy="0 0 0" xyz="0.4100 0 0.012" />
    <axis xyz="0 0 -1" />
    <parent link="jaco_link_2" />
    <child link="jaco_link_3" />
    <limit effort="30" lower="-3.14159265359" upper="3.14159265359" velocity="5" />
  </joint>
  <link name="jaco_link_3">
    <inertial>
      <mass value="1" />
      <inertia ixx="1" ixy="0" ixz="0" iyy="1" iyz="0" izz="1" />
      <origin />
    </inertial>
    <visual>
      <material name="JacoGrey" />
      <origin rpy="0 1.570796327 1.570796327" xyz="0 0 -0.012" />
      <geometry>
        <mesh filename="C:/Users/MohammadhoseinAbdoll/vilma-agent/data/models/custom/9580a4cf/vilma_6axis_robot/vilma_6axis_robot/meshes/joint_4.stl" scale="1.000 1.000 1.000" />
      </geometry>
    </visual>
    <collision>
      <origin rpy="0 1.570796327 1.570796327" xyz="0 0 -0.012" />
      <geometry>
        <mesh filename="C:/Users/MohammadhoseinAbdoll/vilma-agent/data/models/custom/9580a4cf/vilma_6axis_robot/vilma_6axis_robot/meshes/joint_4.stl" scale="1.000 1.000 1.000" />
      </geometry>
    </collision>
  </link>
  <joint name="jaco_joint_4" type="revolute">
    <origin rpy="-1.570796327 0 0" xyz="0 0.24927682300748782 0 " />
    <axis xyz="0 0 -1" />
    <parent link="jaco_link_3" />
    <child link="jaco_link_4" />
    <limit effort="30" lower="-3.14159265359" upper="3.14159265359" velocity="5" />
  </joint>
  <link name="jaco_link_4">
    <inertial>
      <mass value="1" />
      <inertia ixx="1" ixy="0" ixz="0" iyy="1" iyz="0" izz="1" />
      <origin />
    </inertial>
    <visual>
      <material name="JacoGrey" />
      <origin rpy="0 0 -1.570796327" xyz="0 0 -0.042276823" />
      <geometry>
        <mesh filename="C:/Users/MohammadhoseinAbdoll/vilma-agent/data/models/custom/9580a4cf/vilma_6axis_robot/vilma_6axis_robot/meshes/joint_5.stl" scale="0.001 0.001 0.001" />
      </geometry>
    </visual>
    <collision>
      <origin rpy="0 0 -1.570796327" xyz="0 0 -0.042276823" />
      <geometry>
        <mesh filename="C:/Users/MohammadhoseinAbdoll/vilma-agent/data/models/custom/9580a4cf/vilma_6axis_robot/vilma_6axis_robot/meshes/joint_5.stl" scale="0.001 0.001 0.001" />
      </geometry>
    </collision>
  </link>
  <joint name="jaco_joint_5" type="revolute">
    <origin rpy="0.959931089 0 0" xyz="0 -0.069262292 0.048497979" />
    <axis xyz="0 0 -1" />
    <parent link="jaco_link_4" />
    <child link="jaco_link_5" />
    <limit effort="30" lower="-3.14159265359" upper="3.14159265359" velocity="5" />
  </joint>
  <link name="jaco_link_5">
    <inertial>
      <mass value="1.0" />
      <inertia ixx="1" ixy="0" ixz="0" iyy="1" iyz="0" izz="1" />
      <origin />
    </inertial>
    <visual>
      <material name="JacoGrey" />
      <origin rpy="0 -0.959931089 1.570796327" xyz="0 0 -0.042276823" />
      <geometry>
        <mesh filename="C:/Users/MohammadhoseinAbdoll/vilma-agent/data/models/custom/9580a4cf/vilma_6axis_robot/vilma_6axis_robot/meshes/joint_6.stl" scale="0.001 0.001 0.001" />
      </geometry>
    </visual>
    <collision>
      <origin rpy="0 -0.959931089 1.570796327" xyz="0 0 -0.042276823" />
      <geometry>
        <mesh filename="C:/Users/MohammadhoseinAbdoll/vilma-agent/data/models/custom/9580a4cf/vilma_6axis_robot/vilma_6axis_robot/meshes/joint_6.stl" scale="0.001 0.001 0.001" />
      </geometry>
    </collision>
  </link>
  <joint name="jaco_joint_6" type="revolute">
    
    <origin rpy="-0.959931089 0 3.1415926535897931" xyz="0 -0.186174274 0.13036063" />
    
    <axis xyz="0 0 -1" />
    <parent link="jaco_link_5" />
    <child link="jaco_link_6" />
    <limit effort="30" lower="-3.14159265359" upper="3.14159265359" velocity="5" />
  </joint>
  <link name="jaco_link_6">
    <inertial>
      <mass value="0.3" />
      <inertia ixx="1" ixy="0" ixz="0" iyy="1" iyz="0" izz="1" />
      <origin />
    </inertial>
    <visual>
      <material name="JacoGrey" />
      <origin rpy="0 0 -3.1415926535897931" xyz="0 0 -0.1850" />
      
      <geometry>
        <mesh filename="C:/Users/MohammadhoseinAbdoll/vilma-agent/data/models/custom/9580a4cf/vilma_6axis_robot/vilma_6axis_robot/meshes/hand_with_noFinger.stl" scale="0.001 0.001 0.001" />
      </geometry>
    </visual>
    <collision>
      <origin rpy="0 0 -3.1415926535897931" xyz="0 0 -0.1850" />
      
      <geometry>
        <mesh filename="C:/Users/MohammadhoseinAbdoll/vilma-agent/data/models/custom/9580a4cf/vilma_6axis_robot/vilma_6axis_robot/meshes/hand_with_noFinger.stl" scale="0.001 0.001 0.001" />
      </geometry>
    </collision>
  </link>
  <joint name="jaco_gripper_tool_frame_joint" type="fixed">
    <parent link="jaco_link_6" />
    <child link="jaco_gripper_tool_frame" />
    <origin rpy="0.23 -1.570796327 1.570796327" xyz="0 0 -0.08" />
  </joint>
  <link name="jaco_gripper_tool_frame">
    
  </link>
  <joint name="jaco_finger_joint_1" type="revolute">
    
    
    <origin rpy="0 0 3.14159265359" xyz="0.036 -0.021 -0.09" />
    <axis xyz="0 1 0" />
    <parent link="jaco_link_6" />
    <child link="jaco_finger_link_1" />
    <limit effort="30" lower="0.004" upper="1.044" velocity="5" />
  </joint>
  <link name="jaco_finger_link_1">
    <inertial>
      <mass value="0.05" />
      <inertia ixx="1" ixy="0" ixz="0" iyy="1" iyz="0" izz="1" />
      <origin />
    </inertial>
    <visual>
      <origin rpy="0 0 0" xyz="0 0 0" />
      <geometry>
        <mesh filename="C:/Users/MohammadhoseinAbdoll/vilma-agent/data/models/custom/9580a4cf/vilma_6axis_robot/vilma_6axis_robot/meshes/finger.stl" scale="1 1 1" />
      </geometry>
    </visual>
    <collision>
      <origin rpy="0 0 0" xyz="0 0 0" />
      <geometry>
        <mesh filename="C:/Users/MohammadhoseinAbdoll/vilma-agent/data/models/custom/9580a4cf/vilma_6axis_robot/vilma_6axis_robot/meshes/finger.stl" scale="1 1 1" />
      </geometry>
    </collision>
  </link>
  <joint name="jaco_finger_joint_2" type="revolute">
    
    <origin rpy="0 0 3.37159265359" xyz="0.036 0.021 -0.09" />
    <axis xyz="0 1 0" />
    <parent link="jaco_link_6" />
    <child link="jaco_finger_link_2" />
    <limit effort="30" lower="0.004" upper="1.044" velocity="5" />
  </joint>
  <link name="jaco_finger_link_2">
    <inertial>
      <mass value="0.05" />
      <inertia ixx="1" ixy="0" ixz="0" iyy="1" iyz="0" izz="1" />
      <origin />
    </inertial>
    <visual>
      <origin rpy="0 0 0" xyz="0 0 0" />
      <geometry>
        <mesh filename="C:/Users/MohammadhoseinAbdoll/vilma-agent/data/models/custom/9580a4cf/vilma_6axis_robot/vilma_6axis_robot/meshes/finger.stl" scale="1 1 1" />
      </geometry>
    </visual>
    <collision>
      <origin rpy="0 0 0" xyz="0 0 0" />
      <geometry>
        <mesh filename="C:/Users/MohammadhoseinAbdoll/vilma-agent/data/models/custom/9580a4cf/vilma_6axis_robot/vilma_6axis_robot/meshes/finger.stl" scale="1 1 1" />
      </geometry>
    </collision>
  </link>
  <joint name="jaco_finger_joint_3" type="revolute">
    
    <origin rpy="0 0 0.23" xyz="-0.036 -0 -0.09" />
    <axis xyz="0 1 0" />
    <parent link="jaco_link_6" />
    <child link="jaco_finger_link_3" />
    <limit effort="30" lower="0.004" upper="1.044" velocity="5" />
  </joint>
  <link name="jaco_finger_link_3">
    <inertial>
      <mass value="0.05" />
      <inertia ixx="1" ixy="0" ixz="0" iyy="1" iyz="0" izz="1" />
      <origin />
    </inertial>
    <visual>
      <origin rpy="0 0 0" xyz="0 0 0" />
      <geometry>
        <mesh filename="C:/Users/MohammadhoseinAbdoll/vilma-agent/data/models/custom/9580a4cf/vilma_6axis_robot/vilma_6axis_robot/meshes/finger.stl" scale="1 1 1" />
      </geometry>
    </visual>
    <collision>
      <origin rpy="0 0 0" xyz="0 0 0" />
      <geometry>
        <mesh filename="C:/Users/MohammadhoseinAbdoll/vilma-agent/data/models/custom/9580a4cf/vilma_6axis_robot/vilma_6axis_robot/meshes/finger.stl" scale="1 1 1" />
      </geometry>
    </collision>
  </link>
  </robot>