<robot name="openarm">
  <link name="world" />
  <link name="openarm_body_link0">
    <visual name="openarm_body_body_link0_visual">
      <origin xyz="0 0 0" rpy="0 0 0" />
      <geometry>
        <mesh filename="C:/Users/MohammadhoseinAbdoll/vilma-agent/data/Common/robot_models/openarm/meshes/body/v10/collision/body_link0_symp.stl" scale="0.001 0.001 0.001" />
      </geometry>
    </visual>
  </link>
  <joint name="openarm_body_world_joint" type="fixed">
    <parent link="world" />
    <child link="openarm_body_link0" />
    <origin xyz="0 0 0" rpy="0 0 0" />
  </joint>
  <link name="openarm_left_link0">
    <visual name="openarm_left_link0_visual">
      <origin xyz="0 0 0" rpy="0 0 0" />
      <geometry>
        <mesh filename="C:/Users/MohammadhoseinAbdoll/vilma-agent/data/Common/robot_models/openarm/meshes/arm/v10/collision/link0_symp.stl" scale="0.001 -0.001 0.001" />
      </geometry>
    </visual>
  </link>
  <joint name="openarm_left_base_joint" type="fixed">
    <parent link="openarm_body_link0" />
    <child link="openarm_left_link0" />
    <origin xyz="0 0.031 0.698" rpy="-1.5708 0 0" />
  </joint>
  <link name="openarm_left_link1">
    <visual name="openarm_left_link1_visual">
      <origin xyz="-0 0 -0.0625" rpy="0 0 0" />
      <geometry>
        <mesh filename="C:/Users/MohammadhoseinAbdoll/vilma-agent/data/Common/robot_models/openarm/meshes/arm/v10/collision/link1_symp.stl" scale="0.001 -0.001 0.001" />
      </geometry>
    </visual>
  </link>
  <joint name="openarm_left_joint1" type="revolute">
    <parent link="openarm_left_link0" />
    <child link="openarm_left_link1" />
    <origin xyz="0 0 0.0625" rpy="0 0 0" />
    <axis xyz="0 0 1" />
    <limit lower="-5.585055" upper="-0.698133" effort="40" velocity="16.754666" />
  </joint>
  <link name="openarm_left_link2">
    <visual name="openarm_left_link2_visual">
      <origin xyz="0.0301 0 -0.1225" rpy="0 0 0" />
      <geometry>
        <mesh filename="C:/Users/MohammadhoseinAbdoll/vilma-agent/data/Common/robot_models/openarm/meshes/arm/v10/collision/link2_symp.stl" scale="0.001 -0.001 0.001" />
      </geometry>
    </visual>
  </link>
  <joint name="openarm_left_joint2" type="revolute">
    <parent link="openarm_left_link1" />
    <child link="openarm_left_link2" />
    <origin xyz="-0.0301 0 0.06" rpy="-1.570796327 0 0" />
    <axis xyz="-1 0 0" />
    <limit lower="-3.316125327" upper="0.1745326732" effort="40" velocity="16.754666" />
  </joint>
  <link name="openarm_left_link3">
    <visual name="openarm_left_link3_visual">
      <origin xyz="-0 -0 -0.18875" rpy="0 0 0" />
      <geometry>
        <mesh filename="C:/Users/MohammadhoseinAbdoll/vilma-agent/data/Common/robot_models/openarm/meshes/arm/v10/collision/link3_symp.stl" scale="0.001 -0.001 0.001" />
      </geometry>
    </visual>
  </link>
  <joint name="openarm_left_joint3" type="revolute">
    <parent link="openarm_left_link2" />
    <child link="openarm_left_link3" />
    <origin xyz="0.0301 0 0.06625" rpy="0 0 0" />
    <axis xyz="0 0 1" />
    <limit lower="-1.570796" upper="1.570796" effort="27" velocity="5.445426" />
  </joint>
  <link name="openarm_left_link4">
    <visual name="openarm_left_link4_visual">
      <origin xyz="0 -0.0315 -0.3425" rpy="0 0 0" />
      <geometry>
        <mesh filename="C:/Users/MohammadhoseinAbdoll/vilma-agent/data/Common/robot_models/openarm/meshes/arm/v10/collision/link4_symp.stl" scale="0.001 -0.001 0.001" />
      </geometry>
    </visual>
  </link>
  <joint name="openarm_left_joint4" type="revolute">
    <parent link="openarm_left_link3" />
    <child link="openarm_left_link4" />
    <origin xyz="-0 0.0315 0.15375" rpy="0 0 0" />
    <axis xyz="0 1 0" />
    <limit lower="-2.443461" upper="-0" effort="27" velocity="5.445426" />
  </joint>
  <link name="openarm_left_link5">
    <visual name="openarm_left_link5_visual">
      <origin xyz="-0 -0 -0.438" rpy="0 0 0" />
      <geometry>
        <mesh filename="C:/Users/MohammadhoseinAbdoll/vilma-agent/data/Common/robot_models/openarm/meshes/arm/v10/collision/link5_symp.stl" scale="0.001 -0.001 0.001" />
      </geometry>
    </visual>
  </link>
  <joint name="openarm_left_joint5" type="revolute">
    <parent link="openarm_left_link4" />
    <child link="openarm_left_link5" />
    <origin xyz="0 -0.0315 0.0955" rpy="0 0 0" />
    <axis xyz="0 0 1" />
    <limit lower="-1.570796" upper="1.570796" effort="7" velocity="20.943946" />
  </joint>
  <link name="openarm_left_link6">
    <visual name="openarm_left_link6_visual">
      <origin xyz="-0.0375 -0 -0.5585" rpy="0 0 0" />
      <geometry>
        <mesh filename="C:/Users/MohammadhoseinAbdoll/vilma-agent/data/Common/robot_models/openarm/meshes/arm/v10/collision/link6_symp.stl" scale="0.001 -0.001 0.001" />
      </geometry>
    </visual>
  </link>
  <joint name="openarm_left_joint6" type="revolute">
    <parent link="openarm_left_link5" />
    <child link="openarm_left_link6" />
    <origin xyz="0.0375 0 0.1205" rpy="0 0 0" />
    <axis xyz="1 0 0" />
    <limit lower="-0.785398" upper="0.785398" effort="7" velocity="20.943946" />
  </joint>
  <link name="openarm_left_link7">
    <visual name="openarm_left_link7_visual">
      <origin xyz="0 -0 -0.5585" rpy="0 0 0" />
      <geometry>
        <mesh filename="C:/Users/MohammadhoseinAbdoll/vilma-agent/data/Common/robot_models/openarm/meshes/arm/v10/collision/link7_symp.stl" scale="0.001 -0.001 0.001" />
      </geometry>
    </visual>
  </link>
  <joint name="openarm_left_joint7" type="revolute">
    <parent link="openarm_left_link6" />
    <child link="openarm_left_link7" />
    <origin xyz="-0.0375 0 0" rpy="0 0 0" />
    <axis xyz="0 -1 0" />
    <limit lower="-1.570796" upper="1.570796" effort="7" velocity="20.943946" />
  </joint>
  <link name="openarm_right_link0">
    <visual name="openarm_right_link0_visual">
      <origin xyz="0 0 0" rpy="0 0 0" />
      <geometry>
        <mesh filename="C:/Users/MohammadhoseinAbdoll/vilma-agent/data/Common/robot_models/openarm/meshes/arm/v10/collision/link0_symp.stl" scale="0.001 0.001 0.001" />
      </geometry>
    </visual>
  </link>
  <joint name="openarm_right_base_joint" type="fixed">
    <parent link="openarm_body_link0" />
    <child link="openarm_right_link0" />
    <origin xyz="0 -0.031 0.698" rpy="1.5708 0 0" />
  </joint>
  <link name="openarm_right_link1">
    <visual name="openarm_right_link1_visual">
      <origin xyz="-0 0 -0.0625" rpy="0 0 0" />
      <geometry>
        <mesh filename="C:/Users/MohammadhoseinAbdoll/vilma-agent/data/Common/robot_models/openarm/meshes/arm/v10/collision/link1_symp.stl" scale="0.001 0.001 0.001" />
      </geometry>
    </visual>
  </link>
  <joint name="openarm_right_joint1" type="revolute">
    <parent link="openarm_right_link0" />
    <child link="openarm_right_link1" />
    <origin xyz="0 0 0.0625" rpy="0 0 0" />
    <axis xyz="0 0 1" />
    <limit lower="-1.396263" upper="3.490659" effort="40" velocity="16.754666" />
  </joint>
  <link name="openarm_right_link2">
    <visual name="openarm_right_link2_visual">
      <origin xyz="0.0301 0 -0.1225" rpy="0 0 0" />
      <geometry>
        <mesh filename="C:/Users/MohammadhoseinAbdoll/vilma-agent/data/Common/robot_models/openarm/meshes/arm/v10/collision/link2_symp.stl" scale="0.001 0.001 0.001" />
      </geometry>
    </visual>
  </link>
  <joint name="openarm_right_joint2" type="revolute">
    <parent link="openarm_right_link1" />
    <child link="openarm_right_link2" />
    <origin xyz="-0.0301 0 0.06" rpy="1.570796327 0 0" />
    <axis xyz="-1 0 0" />
    <limit lower="-0.1745326732" upper="3.316125327" effort="40" velocity="16.754666" />
  </joint>
  <link name="openarm_right_link3">
    <visual name="openarm_right_link3_visual">
      <origin xyz="-0 -0 -0.18875" rpy="0 0 0" />
      <geometry>
        <mesh filename="C:/Users/MohammadhoseinAbdoll/vilma-agent/data/Common/robot_models/openarm/meshes/arm/v10/collision/link3_symp.stl" scale="0.001 0.001 0.001" />
      </geometry>
    </visual>
  </link>
  <joint name="openarm_right_joint3" type="revolute">
    <parent link="openarm_right_link2" />
    <child link="openarm_right_link3" />
    <origin xyz="0.0301 0 0.06625" rpy="0 0 0" />
    <axis xyz="0 0 1" />
    <limit lower="-1.570796" upper="1.570796" effort="27" velocity="5.445426" />
  </joint>
  <link name="openarm_right_link4">
    <visual name="openarm_right_link4_visual">
      <origin xyz="0 -0.0315 -0.3425" rpy="0 0 0" />
      <geometry>
        <mesh filename="C:/Users/MohammadhoseinAbdoll/vilma-agent/data/Common/robot_models/openarm/meshes/arm/v10/collision/link4_symp.stl" scale="0.001 0.001 0.001" />
      </geometry>
    </visual>
  </link>
  <joint name="openarm_right_joint4" type="revolute">
    <parent link="openarm_right_link3" />
    <child link="openarm_right_link4" />
    <origin xyz="-0 0.0315 0.15375" rpy="0 0 0" />
    <axis xyz="0 1 0" />
    <limit lower="0" upper="2.443461" effort="27" velocity="5.445426" />
  </joint>
  <link name="openarm_right_link5">
    <visual name="openarm_right_link5_visual">
      <origin xyz="-0 -0 -0.438" rpy="0 0 0" />
      <geometry>
        <mesh filename="C:/Users/MohammadhoseinAbdoll/vilma-agent/data/Common/robot_models/openarm/meshes/arm/v10/collision/link5_symp.stl" scale="0.001 0.001 0.001" />
      </geometry>
    </visual>
  </link>
  <joint name="openarm_right_joint5" type="revolute">
    <parent link="openarm_right_link4" />
    <child link="openarm_right_link5" />
    <origin xyz="0 -0.0315 0.0955" rpy="0 0 0" />
    <axis xyz="0 0 1" />
    <limit lower="-1.570796" upper="1.570796" effort="7" velocity="20.943946" />
  </joint>
  <link name="openarm_right_link6">
    <visual name="openarm_right_link6_visual">
      <origin xyz="-0.0375 -0 -0.5585" rpy="0 0 0" />
      <geometry>
        <mesh filename="C:/Users/MohammadhoseinAbdoll/vilma-agent/data/Common/robot_models/openarm/meshes/arm/v10/collision/link6_symp.stl" scale="0.001 0.001 0.001" />
      </geometry>
    </visual>
  </link>
  <joint name="openarm_right_joint6" type="revolute">
    <parent link="openarm_right_link5" />
    <child link="openarm_right_link6" />
    <origin xyz="0.0375 0 0.1205" rpy="0 0 0" />
    <axis xyz="1 0 0" />
    <limit lower="-0.785398" upper="0.785398" effort="7" velocity="20.943946" />
  </joint>
  <link name="openarm_right_link7">
    <visual name="openarm_right_link7_visual">
      <origin xyz="0 -0 -0.5585" rpy="0 0 0" />
      <geometry>
        <mesh filename="C:/Users/MohammadhoseinAbdoll/vilma-agent/data/Common/robot_models/openarm/meshes/arm/v10/collision/link7_symp.stl" scale="0.001 0.001 0.001" />
      </geometry>
    </visual>
  </link>
  <joint name="openarm_right_joint7" type="revolute">
    <parent link="openarm_right_link6" />
    <child link="openarm_right_link7" />
    <origin xyz="-0.0375 0 0" rpy="0 0 0" />
    <axis xyz="0 1 0" />
    <limit lower="-1.570796" upper="1.570796" effort="7" velocity="20.943946" />
  </joint>
  <link name="openarm_left_hand">
    <visual name="openarm_left_hand_visual">
      <origin xyz="0 0 -0.6585" rpy="0 0 0" />
      <geometry>
        <mesh filename="C:/Users/MohammadhoseinAbdoll/vilma-agent/data/Common/robot_models/openarm/meshes/ee/openarm_hand/collision/hand.stl" scale="0.001 0.001 0.001" />
      </geometry>
    </visual>
  </link>
  <joint name="left_openarm_hand_joint" type="fixed">
    <parent link="openarm_left_link7" />
    <child link="openarm_left_hand" />
    <origin xyz="0 0 0.1001" rpy="0 0 0" />
  </joint>
  <link name="openarm_left_hand_tcp" />
  <joint name="openarm_left_hand_tcp_joint" type="fixed">
    <parent link="openarm_left_hand" />
    <child link="openarm_left_hand_tcp" />
    <origin xyz="0 0 0.08" rpy="0 0 0" />
  </joint>
  <link name="openarm_left_left_finger">
    <visual name="openarm_left_left_finger_visual">
      <origin xyz="0 -0.05 -0.673001" rpy="0 0 0" />
      <geometry>
        <mesh filename="C:/Users/MohammadhoseinAbdoll/vilma-agent/data/Common/robot_models/openarm/meshes/ee/openarm_hand/collision/finger.stl" scale="0.001 0.001 0.001" />
      </geometry>
    </visual>
  </link>
  <joint name="openarm_left_finger_joint2" type="prismatic">
    <parent link="openarm_left_hand" />
    <child link="openarm_left_left_finger" />
    <origin xyz="0 0.006 0.015" rpy="0 0 0" />
    <axis xyz="0 1 0" />
    <limit effort="333" lower="0.0" upper="0.044" velocity="10.0" />
    <mimic joint="openarm_left_finger_joint1" />
  </joint>
  <link name="openarm_left_right_finger">
    <visual name="openarm_left_right_finger_visual">
      <origin xyz="0 0.05 -0.673001" rpy="0 0 0" />
      <geometry>
        <mesh filename="C:/Users/MohammadhoseinAbdoll/vilma-agent/data/Common/robot_models/openarm/meshes/ee/openarm_hand/collision/finger.stl" scale="0.001 -0.001 0.001" />
      </geometry>
    </visual>
  </link>
  <joint name="openarm_left_finger_joint1" type="prismatic">
    <parent link="openarm_left_hand" />
    <child link="openarm_left_right_finger" />
    <origin xyz="0 -0.006 0.015" rpy="0 0 0" />
    <axis xyz="0 -1 0" />
    <limit effort="333" lower="0.0" upper="0.044" velocity="10.0" />
  </joint>
  <link name="openarm_right_hand">
    <visual name="openarm_right_hand_visual">
      <origin xyz="0 0 -0.6585" rpy="0 0 0" />
      <geometry>
        <mesh filename="C:/Users/MohammadhoseinAbdoll/vilma-agent/data/Common/robot_models/openarm/meshes/ee/openarm_hand/collision/hand.stl" scale="0.001 0.001 0.001" />
      </geometry>
    </visual>
  </link>
  <joint name="right_openarm_hand_joint" type="fixed">
    <parent link="openarm_right_link7" />
    <child link="openarm_right_hand" />
    <origin xyz="0 0 0.1001" rpy="0 0 0" />
  </joint>
  <link name="openarm_right_hand_tcp" />
  <joint name="openarm_right_hand_tcp_joint" type="fixed">
    <parent link="openarm_right_hand" />
    <child link="openarm_right_hand_tcp" />
    <origin xyz="0 0 0.08" rpy="0 0 0" />
  </joint>
  <link name="openarm_right_left_finger">
    <visual name="openarm_right_left_finger_visual">
      <origin xyz="0 -0.05 -0.673001" rpy="0 0 0" />
      <geometry>
        <mesh filename="C:/Users/MohammadhoseinAbdoll/vilma-agent/data/Common/robot_models/openarm/meshes/ee/openarm_hand/collision/finger.stl" scale="0.001 0.001 0.001" />
      </geometry>
    </visual>
  </link>
  <joint name="openarm_right_finger_joint2" type="prismatic">
    <parent link="openarm_right_hand" />
    <child link="openarm_right_left_finger" />
    <origin xyz="0 0.006 0.015" rpy="0 0 0" />
    <axis xyz="0 1 0" />
    <limit effort="333" lower="0.0" upper="0.044" velocity="10.0" />
    <mimic joint="openarm_right_finger_joint1" />
  </joint>
  <link name="openarm_right_right_finger">
    <visual name="openarm_right_right_finger_visual">
      <origin xyz="0 0.05 -0.673001" rpy="0 0 0" />
      <geometry>
        <mesh filename="C:/Users/MohammadhoseinAbdoll/vilma-agent/data/Common/robot_models/openarm/meshes/ee/openarm_hand/collision/finger.stl" scale="0.001 -0.001 0.001" />
      </geometry>
    </visual>
  </link>
  <joint name="openarm_right_finger_joint1" type="prismatic">
    <parent link="openarm_right_hand" />
    <child link="openarm_right_right_finger" />
    <origin xyz="0 -0.006 0.015" rpy="0 0 0" />
    <axis xyz="0 -1 0" />
    <limit effort="333" lower="0.0" upper="0.044" velocity="10.0" />
  </joint>
</robot>